Failure when fetching the discord_cloudsync@0 module (https://trello.com/c/ndwX7a4y)

P3: Will eventually be fixed,
low

Created: 2018-10-25T02:56:26.039Z
Latest Update: 2018-10-25T03:56:14.927Z

Reported by Emma#8932

####Steps to reproduce:
- Start up Discord

####Expected result:
Discord starts up normally.
####Actual result:
Discord shows a "update failed" message for a split second, due to the discord_cloudsync download URL leading to a 403.
####Client settings:
Release Channel: stable, Build Number: 26773, Version Hash: 951c871c16ef537ca226b5ae3b532788a605
####System settings:
Ubuntu 18.04.1 LTS

22016

Card Log
========
### Added by Bug Bot on 2018-10-25T02:56:26.039Z


### Can reproduce.
Can reproduce, while Discord does launch, it does seem to give the noted error in the log - Linux Ubuntu 18.04.1, Discord Stable 26847 - For future reference, the log can be found at "~/.config/discord/modules.log" or "~/snap/discord/current/.config/discord/modules.log" (if installed through Ubuntu Package Manager

Haruüòçüíú#6660 - Bug Bot on 2018-10-25T02:56:33.369Z


### Can reproduce.
CR. Only happens in Stable version of Discord. I can see the error in my terminal. ArchLinux x64 - Linux Kernel 4.18.16-1 - GNOME 3.30.1 - Discord Stable Build 26902

Frances Picard#6209 - Bug Bot on 2018-10-25T02:56:38.462Z


### Can reproduce.
Ubuntu 16.04.3; Stable 26902; was easier to see in console and was only able to reproduce on stable

Rauf#0001 - Bug Bot on 2018-10-25T02:56:43.369Z


### Can reproduce.
Arch Linux, kernel 4.18.2, Discord Stable 26902

sans#8719 - Bug Bot on 2018-10-25T03:39:19.965Z


### verified.  - Clayton on 2018-10-25T03:56:07.273Z


### Moved from User Reported to Discord Verified Bugs by Clayton on 2018-10-25T03:56:14.912Z

List
====
Discord Verified Bugs

Members
=======
None
